<?xml version="1.0" encoding="UTF-8"?>
<mujoco model="Leap Hand">
  <compiler angle="radian"/>
  <option timestep="0.0002" integrator="Euler">
    <!-- <flag contact="disable" gravity="disable"/> -->
    <flag gravity="enable"/>
  </option>

  <asset>
    <mesh name="palm_lower" file="palm_lower.stl"/>
    <mesh name="mcp_joint" file="mcp_joint.stl"/>
    <mesh name="pip" file="pip.stl"/>
    <mesh name="dip" file="dip.stl"/>
    <mesh name="fingertip" file="fingertip.stl"/>
    <mesh name="thumb_dip" file="thumb_dip.stl"/>
    <mesh name="thumb_fingertip" file="thumb_fingertip.stl"/>
    <mesh name="thumb_pip" file="thumb_pip.stl"/>
    <texture name="grid" type="2d" builtin="checker" width="512" height="512" rgb1=".1 .2 .3" rgb2=".2 .3 .4"/>
    <material name="grid" texture="grid" texrepeat="1 1" texuniform="true" reflectance="0"/>
    <material name="box" rgba="0.2 0.6 0.9 1" specular="0.5" reflectance="0.1"/>
  </asset>



  <worldbody>

    <light name="top" pos="0 0 1"/>
    <!-- <geom type="plane" pos="0 0 -0.025" size="3 3 .01" material="grid"/> -->
    <camera name="closeup" mode="fixed" pos="-0.02 1 0.025" xyaxes="-1 0 0 0 0 1"/>
    <camera name="top" mode="fixed" pos="0 0 0.8" xyaxes="1 0 0 0 1 0"/>

      
    <body name="palm" pos="0 0 0">
    <geom name="palm" pos="-0.0200952 0.0257578 -0.0347224" type="mesh" rgba="0.603922 0.14902 0.14902 1" mesh="palm_lower"/>
  

    <body name="mcp_joint_3" pos="-0.00709525 -0.0678422 -0.0187224" quat="0.5 0.5 0.5 -0.5">
      <joint name="9" pos="0 0 0" axis="0 0 -1" range="-0.314 2.23" damping="0.1"/>
      <geom pos="0.0084069 0.00776624 0.0146574" quat="1 0 0 0" type="mesh" rgba="0.866667 0.866667 0.0509804 1" mesh="mcp_joint"/>
      <site pos="0.007 0 0.015" name="3_1"/>
      <body name="pip_3" pos="-0.0122 0.0381 0.0145" quat="0.5 -0.5 -0.5 0.5">
        <joint name="8" pos="0 0 0" axis="0 0 -1" range="-1.047 1.047" damping="0.1"/>
        <geom pos="0.00964336 0.0003 0.000784034" quat="0.5 -0.5 -0.5 -0.5" type="mesh" rgba="0.74902 0.74902 0.74902 1" mesh="pip"/>
        <site pos="0 0 -0.023" name="3_2"/>
        <body name="dip_3" pos="0.015 0.0143 -0.013" quat="0.5 0.5 -0.5 0.5">
          <joint name="10" pos="0 0 0" axis="0 0 -1" range="-0.506 1.885" damping="0.1"/>
          <geom pos="0.0211334 -0.00843212 0.00978509" quat="0 -1 0 0" type="mesh" rgba="0.866667 0.866667 0.0509804 1" mesh="dip"/>
          <site pos="-0.009 -0.031 0.015" name="3_3"/>
          <body name="fingertip_3" pos="0 -0.0361 0.0002">
            <joint name="11" pos="0 0 0" axis="0 0 -1" range="-0.366 2.042" damping="0.1"/>
            <geom pos="0.0132864 -0.00611424 0.0145" quat="0 1 0 0" type="mesh" rgba="0.866667 0.866667 0.0509804 1" mesh="fingertip"/>
            <site pos="-0.01 -0.04 0.015" name="3_4"/>
          </body>
        </body>
      </body>
    </body>
    </body>

  </worldbody>

<actuator>
    <!-- <motor name="palm_slide" joint="palm_slide"/>
    <motor name="wrist" joint="wrist"/> -->
    <motor name="motor_9" joint="9"/>
    <motor name="motor_8" joint="8"/>
    <motor name="motor_10" joint="10"/>
    <motor name="motor_11" joint="11"/>

  </actuator>

<contact>
<exclude body1="palm" body2="mcp_joint_3"/>
</contact>

</mujoco>
