<?xml version="1.0" encoding="UTF-8"?>
<mujoco model="Leap Hand">
  <compiler angle="radian"/>
  <option timestep="0.0002" integrator="Euler">
    <!-- <flag contact="disable" gravity="disable"/> -->
    <flag gravity="enable"/>
  </option>

  <asset>
    <mesh name="palm_lower" file="palm_lower.stl"/>
    <mesh name="mcp_joint" file="mcp_joint.stl"/>
    <mesh name="pip" file="pip.stl"/>
    <mesh name="dip" file="dip.stl"/>
    <mesh name="fingertip" file="fingertip.stl"/>
    <mesh name="thumb_dip" file="thumb_dip.stl"/>
    <mesh name="thumb_fingertip" file="thumb_fingertip.stl"/>
    <mesh name="thumb_pip" file="thumb_pip.stl"/>
    <texture name="grid" type="2d" builtin="checker" width="512" height="512" rgb1=".1 .2 .3" rgb2=".2 .3 .4"/>
    <material name="grid" texture="grid" texrepeat="1 1" texuniform="true" reflectance="0"/>
    <material name="box" rgba="0.2 0.6 0.9 1" specular="0.5" reflectance="0.1"/>
  </asset>



  <worldbody>

    <light name="top" pos="0 0 1"/>
    <!-- <geom type="plane" pos="0 0 -0.025" size="3 3 .01" material="grid"/> -->
    <camera name="closeup" mode="fixed" pos="-0.02 1 0.025" xyaxes="-1 0 0 0 0 1"/>
    <camera name="top" mode="fixed" pos="0 0 0.8" xyaxes="1 0 0 0 1 0"/>

      
    <body name="palm" pos="0 0 0">
    <geom name="palm" pos="-0.0200952 0.0257578 -0.0347224" type="mesh" rgba="0.603922 0.14902 0.14902 1" mesh="palm_lower"/>

    <body name="pip_4" pos="-0.0693952 -0.00124224 -0.0216224" quat="0.707107 0 0.707107 0">
      <!-- <inertial pos="0 0 0" quat="0.709913 0.704273 -0.000363156 0.00475427" mass="0.032" diaginertia="4.7981e-06 4.23406e-06 2.86184e-06"/> -->
      <joint name="12" pos="0 0 0" axis="0 0 -1" range="-0.349 2.094" damping="0.1"/>
      <geom pos="-0.00535664 0.0003 0.000784034" quat="0.5 -0.5 -0.5 -0.5" type="mesh" rgba="0.74902 0.74902 0.74902 1" mesh="pip"/>
      <body name="thumb_pip_4" pos="0 0.0143 -0.013" quat="0.5 0.5 -0.5 0.5">
        <!-- <inertial pos="0 0 0" mass="0.003" diaginertia="5.93e-07 5.49e-07 2.24e-07"/> -->
        <joint name="13" pos="0 0 0" axis="0 0 -1" range="-0.47 2.443" damping="0.1"/>
        <geom pos="0.0119619 0 -0.0158526" quat="0.707107 0.707107 0 0" type="mesh" rgba="0.866667 0.866667 0.0509804 1" mesh="thumb_pip"/>
        <site name="4_1" pos="0.012 0 -0.027"/>
        <body name="thumb_dip_4" pos="0 0.0145 -0.017" quat="0.707107 -0.707107 0 0">
          <!-- <inertial pos="0 0 0" quat="0.708624 0.704906 0.00637342 0.0303153" mass="0.038" diaginertia="8.48742e-06 7.67823e-06 3.82835e-06"/> -->
          <joint name="14" pos="0 0 0" axis="0 0 -1" range="-1.20 1.90" damping="0.1"/>
          <geom pos="0.0439687 0.057953 -0.00862868" quat="1 0 0 0" type="mesh" rgba="0.866667 0.866667 0.0509804 1" mesh="thumb_dip"/>
          <body name="thumb_fingertip_4" pos="0 0.0466 0.0002" quat="0 0 0 1">
            <!-- <inertial pos="0 0 0" quat="0.704307 0.709299 0.006848 -0.0282727" mass="0.049" diaginertia="2.03882e-05 1.98443e-05 4.32049e-06"/> -->
            <joint name="15" pos="0 0 0" axis="0 0 -1" range="-1.34 1.88" damping="0.1"/>
            <geom pos="0.0625595 0.0784597 0.0489929" type="mesh" rgba="0.603922 0.14902 0.14902 1" mesh="thumb_fingertip"/>
            <site  name="4_2" pos="-0.01 -0.011 -0.015"/>
            <site  name="4_3" pos="-0.01 -0.046 -0.015"/>
          </body>
        </body>
      </body>
    </body>
    </body>

  </worldbody>

<actuator>
    <motor name="motor_12" joint="12"/>
    <motor name="motor_13" joint="13"/>
    <motor name="motor_14" joint="14"/>
    <motor name="motor_15" joint="15"/>
  </actuator>

<contact>
<exclude body1="palm" body2="pip_4"/>
</contact>

</mujoco>
